2017-09-22 14:23:51,787 db.py [line:27]-select  ERROR "Exec: SELECT * FROM users WHERE password="321654" and username="tailoryang";,"Error: Traceback (most recent call last):
  File "D:\python\homework\day09\db.py", line 23, in select
    cursor.execute(sql)
  File "C:\Users\yng\AppData\Local\Programs\Python\Python35\lib\site-packages\mysql\connector\cursor.py", line 515, in execute
    self._handle_result(self._connection.cmd_query(stmt))
  File "C:\Users\yng\AppData\Local\Programs\Python\Python35\lib\site-packages\mysql\connector\connection.py", line 488, in cmd_query
    result = self._handle_result(self._send_cmd(ServerCmd.QUERY, query))
  File "C:\Users\yng\AppData\Local\Programs\Python\Python35\lib\site-packages\mysql\connector\connection.py", line 395, in _handle_result
    raise errors.get_exception(packet)
mysql.connector.errors.ProgrammingError: 1146 (42S02): Table 'reboot15.users' doesn't exist
"
2017-09-22 14:25:34,720 user.py [line:12]-index  INFO "INFO: ['username']"
2017-09-22 14:26:00,909 user.py [line:12]-index  INFO "INFO: ['username']"
2017-09-22 14:26:00,909 user.py [line:12]-index  INFO "INFO: ['username']"
2017-09-22 14:27:28,548 user.py [line:12]-index  INFO user "INFO: ['username']"
2017-09-22 14:28:23,707 user.py [line:12]-index  INFO user "INFO: tailoryang "
2017-09-22 14:30:30,230 user.py [line:28]-login  INFO user "INFO: tailoryang is login success"
2017-09-22 14:30:31,754 user.py [line:12]-index  INFO user "INFO: tailoryang is Is visiting"
2017-09-22 14:30:31,754 user.py [line:12]-index  INFO user "INFO: tailoryang is Is visiting"
2017-09-22 14:34:06,992 user.py [line:40]-loginout  INFO user "INFO: ['username'] logout"
2017-09-22 14:34:19,863 user.py [line:28]-login  INFO user "INFO: tailoryang is login success"
2017-09-22 14:34:19,863 user.py [line:28]-login  INFO user "INFO: tailoryang is login success"
2017-09-22 14:34:21,138 user.py [line:12]-index  INFO user "INFO: tailoryang is Is visiting"
2017-09-22 14:34:21,138 user.py [line:12]-index  INFO user "INFO: tailoryang is Is visiting"
2017-09-22 14:34:21,138 user.py [line:12]-index  INFO user "INFO: tailoryang is Is visiting"
2017-09-22 14:34:22,717 user.py [line:40]-loginout  INFO user "INFO: ['username'] logout"
2017-09-22 14:34:22,717 user.py [line:40]-loginout  INFO user "INFO: ['username'] logout"
2017-09-22 14:34:22,717 user.py [line:40]-loginout  INFO user "INFO: ['username'] logout"
2017-09-22 14:34:22,717 user.py [line:40]-loginout  INFO user "INFO: ['username'] logout"
2017-09-22 14:36:05,495 user.py [line:28]-login  INFO user "INFO: tailoryang is login success"
2017-09-22 14:36:06,498 user.py [line:12]-index  INFO user "INFO: tailoryang is Is visiting"
2017-09-22 14:36:06,498 user.py [line:12]-index  INFO user "INFO: tailoryang is Is visiting"
2017-09-22 14:56:55,858 user.py [line:60]-userinfo  INFO user INFO : tailoryang is view his info 
2017-09-22 14:57:15,582 user.py [line:60]-userinfo  INFO user INFO : tailoryang is view his info 
2017-09-22 15:06:35,548 user.py [line:55]-userinfo  INFO user INFO: ['username'] is change 123's info
2017-09-22 15:08:55,933 user.py [line:55]-userinfo  INFO user INFO: ['username'] is change 123's info
2017-09-22 15:09:42,263 user.py [line:55]-userinfo  INFO user INFO: ['username'] is change www1's info
2017-09-22 15:15:56,378 user.py [line:55]-userinfo  INFO user INFO: ['username'] is change admin's info
2017-09-22 15:19:39,155 user.py [line:69]-userinfo  INFO user INFO : tailoryang is view his info 
2017-09-22 15:21:16,563 user.py [line:69]-userinfo  INFO user INFO : tailoryang is view his info 
2017-09-22 15:21:18,765 user.py [line:63]-userinfo  INFO user INFO: ['username'] is change tailoryang's info
2017-09-22 15:22:18,584 user.py [line:69]-userinfo  INFO user INFO : tailoryang is view his info 
2017-09-22 15:22:32,068 user.py [line:69]-userinfo  INFO user INFO : tailoryang is view his info 
2017-09-22 15:22:35,402 user.py [line:63]-userinfo  INFO user INFO: ['username'] is change tailoryang's info
2017-09-22 15:22:42,342 user.py [line:69]-userinfo  INFO user INFO : tailoryang is view his info 
2017-09-22 15:22:47,406 user.py [line:69]-userinfo  INFO user INFO : tailoryang is view his info 
2017-09-22 15:22:55,995 user.py [line:69]-userinfo  INFO user INFO : tailoryang is view his info 
2017-09-22 15:23:31,278 user.py [line:90]-loginout  INFO user "INFO: ['username'] logout"
2017-09-22 15:23:41,877 user.py [line:28]-login  INFO user "INFO: admin is login success"
2017-09-22 15:23:43,040 user.py [line:12]-index  INFO user "INFO: admin is Is visiting"
2017-09-22 16:47:07,127 user.py [line:12]-index  INFO user "INFO: admin is Is visiting"
2017-09-22 16:47:10,997 user.py [line:69]-userinfo  INFO user INFO : admin is view his info 
2017-09-22 16:47:12,710 user.py [line:63]-userinfo  INFO user INFO: ['username'] is change admin's info
2017-09-22 18:17:35,698 db.py [line:53]-add  ERROR db "Exec: INSERT INTO idc () VALUES();,"Error: Traceback (most recent call last):
  File "D:\python\homework\day09\db.py", line 50, in add
    cursor.execute(sql)
  File "C:\Users\yng\AppData\Local\Programs\Python\Python35\lib\site-packages\mysql\connector\cursor.py", line 515, in execute
    self._handle_result(self._connection.cmd_query(stmt))
  File "C:\Users\yng\AppData\Local\Programs\Python\Python35\lib\site-packages\mysql\connector\connection.py", line 488, in cmd_query
    result = self._handle_result(self._send_cmd(ServerCmd.QUERY, query))
  File "C:\Users\yng\AppData\Local\Programs\Python\Python35\lib\site-packages\mysql\connector\connection.py", line 395, in _handle_result
    raise errors.get_exception(packet)
mysql.connector.errors.IntegrityError: 1062 (23000): Duplicate entry '0' for key 'PRIMARY'
"
2017-09-22 18:19:38,464 db.py [line:53]-add  ERROR db "Exec: INSERT INTO idc () VALUES();,"Error: Traceback (most recent call last):
  File "D:\python\homework\day09\db.py", line 50, in add
    cursor.execute(sql)
  File "C:\Users\yng\AppData\Local\Programs\Python\Python35\lib\site-packages\mysql\connector\cursor.py", line 515, in execute
    self._handle_result(self._connection.cmd_query(stmt))
  File "C:\Users\yng\AppData\Local\Programs\Python\Python35\lib\site-packages\mysql\connector\connection.py", line 488, in cmd_query
    result = self._handle_result(self._send_cmd(ServerCmd.QUERY, query))
  File "C:\Users\yng\AppData\Local\Programs\Python\Python35\lib\site-packages\mysql\connector\connection.py", line 395, in _handle_result
    raise errors.get_exception(packet)
mysql.connector.errors.IntegrityError: 1062 (23000): Duplicate entry '0' for key 'PRIMARY'
"
2017-09-22 18:21:10,153 db.py [line:53]-add  ERROR db "Exec: INSERT INTO idc (address,name,name_cn,userid) VALUES("111111","003","llw","22");,"Error: Traceback (most recent call last):
  File "D:\python\homework\day09\db.py", line 50, in add
    cursor.execute(sql)
  File "C:\Users\yng\AppData\Local\Programs\Python\Python35\lib\site-packages\mysql\connector\cursor.py", line 515, in execute
    self._handle_result(self._connection.cmd_query(stmt))
  File "C:\Users\yng\AppData\Local\Programs\Python\Python35\lib\site-packages\mysql\connector\connection.py", line 488, in cmd_query
    result = self._handle_result(self._send_cmd(ServerCmd.QUERY, query))
  File "C:\Users\yng\AppData\Local\Programs\Python\Python35\lib\site-packages\mysql\connector\connection.py", line 395, in _handle_result
    raise errors.get_exception(packet)
mysql.connector.errors.IntegrityError: 1062 (23000): Duplicate entry '0' for key 'PRIMARY'
"
2017-09-22 18:21:49,377 db.py [line:53]-add  ERROR db "Exec: INSERT INTO idc (address,userid,name,name_cn) VALUES("qqqq","22","003","llw");,"Error: Traceback (most recent call last):
  File "D:\python\homework\day09\db.py", line 50, in add
    cursor.execute(sql)
  File "C:\Users\yng\AppData\Local\Programs\Python\Python35\lib\site-packages\mysql\connector\cursor.py", line 515, in execute
    self._handle_result(self._connection.cmd_query(stmt))
  File "C:\Users\yng\AppData\Local\Programs\Python\Python35\lib\site-packages\mysql\connector\connection.py", line 488, in cmd_query
    result = self._handle_result(self._send_cmd(ServerCmd.QUERY, query))
  File "C:\Users\yng\AppData\Local\Programs\Python\Python35\lib\site-packages\mysql\connector\connection.py", line 395, in _handle_result
    raise errors.get_exception(packet)
mysql.connector.errors.IntegrityError: 1062 (23000): Duplicate entry '0' for key 'PRIMARY'
"
2017-09-22 18:25:10,249 user.py [line:12]-index  INFO user "INFO: admin is Is visiting"
2017-09-22 20:54:28,330 user.py [line:28]-login  INFO user "INFO: tailoryang is login success"
2017-09-22 20:54:29,661 user.py [line:12]-index  INFO user "INFO: tailoryang is Is visiting"
2017-09-22 20:55:28,465 user.py [line:69]-userinfo  INFO user INFO : tailoryang is view his info 
2017-09-23 05:35:16,732 user.py [line:28]-login  INFO user "INFO: tailoryang is login success"
2017-09-23 05:35:18,754 user.py [line:12]-index  INFO user "INFO: tailoryang is Is visiting"
2017-09-23 06:09:59,885 db.py [line:53]-add  ERROR db "Exec: INSERT INTO idc (idc_id,power,u_num,userid,name) VALUES("1","220","13","1","wwe");,"Error: Traceback (most recent call last):
  File "D:\python\homework\day09\db.py", line 50, in add
    cursor.execute(sql)
  File "C:\Users\yng\AppData\Local\Programs\Python\Python35\lib\site-packages\mysql\connector\cursor.py", line 515, in execute
    self._handle_result(self._connection.cmd_query(stmt))
  File "C:\Users\yng\AppData\Local\Programs\Python\Python35\lib\site-packages\mysql\connector\connection.py", line 488, in cmd_query
    result = self._handle_result(self._send_cmd(ServerCmd.QUERY, query))
  File "C:\Users\yng\AppData\Local\Programs\Python\Python35\lib\site-packages\mysql\connector\connection.py", line 395, in _handle_result
    raise errors.get_exception(packet)
mysql.connector.errors.ProgrammingError: 1054 (42S22): Unknown column 'idc_id' in 'field list'
"
2017-09-23 06:12:12,866 db.py [line:53]-add  ERROR db "Exec: INSERT INTO cabinet (userid,idc_id,name,u_num,power) VALUES("1","1","wwe","23","220");,"Error: Traceback (most recent call last):
  File "D:\python\homework\day09\db.py", line 50, in add
    cursor.execute(sql)
  File "C:\Users\yng\AppData\Local\Programs\Python\Python35\lib\site-packages\mysql\connector\cursor.py", line 515, in execute
    self._handle_result(self._connection.cmd_query(stmt))
  File "C:\Users\yng\AppData\Local\Programs\Python\Python35\lib\site-packages\mysql\connector\connection.py", line 488, in cmd_query
    result = self._handle_result(self._send_cmd(ServerCmd.QUERY, query))
  File "C:\Users\yng\AppData\Local\Programs\Python\Python35\lib\site-packages\mysql\connector\connection.py", line 395, in _handle_result
    raise errors.get_exception(packet)
mysql.connector.errors.ProgrammingError: 1054 (42S22): Unknown column 'userid' in 'field list'
"
2017-09-23 06:13:10,721 db.py [line:53]-add  ERROR db "Exec: INSERT INTO cabinet (userid,idc_id,power,u_num,name) VALUES("1","1","220","2","wwe");,"Error: Traceback (most recent call last):
  File "D:\python\homework\day09\db.py", line 50, in add
    cursor.execute(sql)
  File "C:\Users\yng\AppData\Local\Programs\Python\Python35\lib\site-packages\mysql\connector\cursor.py", line 515, in execute
    self._handle_result(self._connection.cmd_query(stmt))
  File "C:\Users\yng\AppData\Local\Programs\Python\Python35\lib\site-packages\mysql\connector\connection.py", line 488, in cmd_query
    result = self._handle_result(self._send_cmd(ServerCmd.QUERY, query))
  File "C:\Users\yng\AppData\Local\Programs\Python\Python35\lib\site-packages\mysql\connector\connection.py", line 395, in _handle_result
    raise errors.get_exception(packet)
mysql.connector.errors.ProgrammingError: 1054 (42S22): Unknown column 'userid' in 'field list'
"
2017-09-23 06:13:27,150 db.py [line:53]-add  ERROR db "Exec: INSERT INTO cabinet (userid,idc_id,power,u_num,name) VALUES("1","1","220","2","wwe");,"Error: Traceback (most recent call last):
  File "D:\python\homework\day09\db.py", line 50, in add
    cursor.execute(sql)
  File "C:\Users\yng\AppData\Local\Programs\Python\Python35\lib\site-packages\mysql\connector\cursor.py", line 515, in execute
    self._handle_result(self._connection.cmd_query(stmt))
  File "C:\Users\yng\AppData\Local\Programs\Python\Python35\lib\site-packages\mysql\connector\connection.py", line 488, in cmd_query
    result = self._handle_result(self._send_cmd(ServerCmd.QUERY, query))
  File "C:\Users\yng\AppData\Local\Programs\Python\Python35\lib\site-packages\mysql\connector\connection.py", line 395, in _handle_result
    raise errors.get_exception(packet)
mysql.connector.errors.ProgrammingError: 1054 (42S22): Unknown column 'userid' in 'field list'
"
2017-09-23 06:13:38,153 db.py [line:53]-add  ERROR db "Exec: INSERT INTO cabinet (userid,idc_id,power,u_num,name) VALUES("1","1","220","12","wwe");,"Error: Traceback (most recent call last):
  File "D:\python\homework\day09\db.py", line 50, in add
    cursor.execute(sql)
  File "C:\Users\yng\AppData\Local\Programs\Python\Python35\lib\site-packages\mysql\connector\cursor.py", line 515, in execute
    self._handle_result(self._connection.cmd_query(stmt))
  File "C:\Users\yng\AppData\Local\Programs\Python\Python35\lib\site-packages\mysql\connector\connection.py", line 488, in cmd_query
    result = self._handle_result(self._send_cmd(ServerCmd.QUERY, query))
  File "C:\Users\yng\AppData\Local\Programs\Python\Python35\lib\site-packages\mysql\connector\connection.py", line 395, in _handle_result
    raise errors.get_exception(packet)
mysql.connector.errors.ProgrammingError: 1054 (42S22): Unknown column 'userid' in 'field list'
"
2017-09-23 06:16:33,531 db.py [line:53]-add  ERROR db "Exec: INSERT INTO cabinet (userid,power,name,u_num,idc_id) VALUES("1","220","wwe","12","1");,"Error: Traceback (most recent call last):
  File "D:\python\homework\day09\db.py", line 50, in add
    cursor.execute(sql)
  File "C:\Users\yng\AppData\Local\Programs\Python\Python35\lib\site-packages\mysql\connector\cursor.py", line 515, in execute
    self._handle_result(self._connection.cmd_query(stmt))
  File "C:\Users\yng\AppData\Local\Programs\Python\Python35\lib\site-packages\mysql\connector\connection.py", line 488, in cmd_query
    result = self._handle_result(self._send_cmd(ServerCmd.QUERY, query))
  File "C:\Users\yng\AppData\Local\Programs\Python\Python35\lib\site-packages\mysql\connector\connection.py", line 395, in _handle_result
    raise errors.get_exception(packet)
mysql.connector.errors.ProgrammingError: 1054 (42S22): Unknown column 'userid' in 'field list'
"
2017-09-23 06:17:16,556 db.py [line:53]-add  ERROR db "Exec: INSERT INTO cabinet (u_num,power,userid,name,idc_id) VALUES("12","220","1","wwe","1");,"Error: Traceback (most recent call last):
  File "D:\python\homework\day09\db.py", line 50, in add
    cursor.execute(sql)
  File "C:\Users\yng\AppData\Local\Programs\Python\Python35\lib\site-packages\mysql\connector\cursor.py", line 515, in execute
    self._handle_result(self._connection.cmd_query(stmt))
  File "C:\Users\yng\AppData\Local\Programs\Python\Python35\lib\site-packages\mysql\connector\connection.py", line 488, in cmd_query
    result = self._handle_result(self._send_cmd(ServerCmd.QUERY, query))
  File "C:\Users\yng\AppData\Local\Programs\Python\Python35\lib\site-packages\mysql\connector\connection.py", line 395, in _handle_result
    raise errors.get_exception(packet)
mysql.connector.errors.ProgrammingError: 1054 (42S22): Unknown column 'userid' in 'field list'
"
2017-09-23 07:24:21,361 db.py [line:53]-add  ERROR db "Exec: INSERT INTO cabinet (idc_id,power,name,u_num) VALUES("1","222","wwe","12");,"Error: Traceback (most recent call last):
  File "D:\python\homework\day09\db.py", line 50, in add
    cursor.execute(sql)
  File "C:\Users\yng\AppData\Local\Programs\Python\Python35\lib\site-packages\mysql\connector\cursor.py", line 515, in execute
    self._handle_result(self._connection.cmd_query(stmt))
  File "C:\Users\yng\AppData\Local\Programs\Python\Python35\lib\site-packages\mysql\connector\connection.py", line 488, in cmd_query
    result = self._handle_result(self._send_cmd(ServerCmd.QUERY, query))
  File "C:\Users\yng\AppData\Local\Programs\Python\Python35\lib\site-packages\mysql\connector\connection.py", line 395, in _handle_result
    raise errors.get_exception(packet)
mysql.connector.errors.IntegrityError: 1062 (23000): Duplicate entry 'wwe' for key 'name'
"
2017-09-23 07:47:13,233 db.py [line:36]-update  ERROR db "Exec: UPDATE idc SET u_num='11',userid='4',id='1',idc_id='undefined',power='220',name='wwe' WHERE id = 1;,"Error: Traceback (most recent call last):
  File "D:\python\homework\day09\db.py", line 33, in update
    cursor.execute(sql)
  File "C:\Users\yng\AppData\Local\Programs\Python\Python35\lib\site-packages\mysql\connector\cursor.py", line 515, in execute
    self._handle_result(self._connection.cmd_query(stmt))
  File "C:\Users\yng\AppData\Local\Programs\Python\Python35\lib\site-packages\mysql\connector\connection.py", line 488, in cmd_query
    result = self._handle_result(self._send_cmd(ServerCmd.QUERY, query))
  File "C:\Users\yng\AppData\Local\Programs\Python\Python35\lib\site-packages\mysql\connector\connection.py", line 395, in _handle_result
    raise errors.get_exception(packet)
mysql.connector.errors.ProgrammingError: 1054 (42S22): Unknown column 'u_num' in 'field list'
"
2017-09-23 07:47:39,532 db.py [line:36]-update  ERROR db "Exec: UPDATE idc SET u_num='11',userid='4',id='1',idc_id='undefined',power='220',name='wwe' WHERE id = 1;,"Error: Traceback (most recent call last):
  File "D:\python\homework\day09\db.py", line 33, in update
    cursor.execute(sql)
  File "C:\Users\yng\AppData\Local\Programs\Python\Python35\lib\site-packages\mysql\connector\cursor.py", line 515, in execute
    self._handle_result(self._connection.cmd_query(stmt))
  File "C:\Users\yng\AppData\Local\Programs\Python\Python35\lib\site-packages\mysql\connector\connection.py", line 488, in cmd_query
    result = self._handle_result(self._send_cmd(ServerCmd.QUERY, query))
  File "C:\Users\yng\AppData\Local\Programs\Python\Python35\lib\site-packages\mysql\connector\connection.py", line 395, in _handle_result
    raise errors.get_exception(packet)
mysql.connector.errors.ProgrammingError: 1054 (42S22): Unknown column 'u_num' in 'field list'
"
2017-09-23 07:47:49,431 db.py [line:36]-update  ERROR db "Exec: UPDATE idc SET u_num='12',userid='3',id='1',idc_id='undefined',power='220',name='wwe' WHERE id = 1;,"Error: Traceback (most recent call last):
  File "D:\python\homework\day09\db.py", line 33, in update
    cursor.execute(sql)
  File "C:\Users\yng\AppData\Local\Programs\Python\Python35\lib\site-packages\mysql\connector\cursor.py", line 515, in execute
    self._handle_result(self._connection.cmd_query(stmt))
  File "C:\Users\yng\AppData\Local\Programs\Python\Python35\lib\site-packages\mysql\connector\connection.py", line 488, in cmd_query
    result = self._handle_result(self._send_cmd(ServerCmd.QUERY, query))
  File "C:\Users\yng\AppData\Local\Programs\Python\Python35\lib\site-packages\mysql\connector\connection.py", line 395, in _handle_result
    raise errors.get_exception(packet)
mysql.connector.errors.ProgrammingError: 1054 (42S22): Unknown column 'u_num' in 'field list'
"
2017-09-23 07:49:10,441 db.py [line:36]-update  ERROR db "Exec: UPDATE idc SET idc_id='3',u_num='12',name='wwe',id='1',power='220' WHERE id = 1;,"Error: Traceback (most recent call last):
  File "D:\python\homework\day09\db.py", line 33, in update
    cursor.execute(sql)
  File "C:\Users\yng\AppData\Local\Programs\Python\Python35\lib\site-packages\mysql\connector\cursor.py", line 515, in execute
    self._handle_result(self._connection.cmd_query(stmt))
  File "C:\Users\yng\AppData\Local\Programs\Python\Python35\lib\site-packages\mysql\connector\connection.py", line 488, in cmd_query
    result = self._handle_result(self._send_cmd(ServerCmd.QUERY, query))
  File "C:\Users\yng\AppData\Local\Programs\Python\Python35\lib\site-packages\mysql\connector\connection.py", line 395, in _handle_result
    raise errors.get_exception(packet)
mysql.connector.errors.ProgrammingError: 1054 (42S22): Unknown column 'idc_id' in 'field list'
"
2017-09-23 07:49:35,026 db.py [line:36]-update  ERROR db "Exec: UPDATE idc SET power='220',id='1',u_num='12',idc_id='3',name='wwe' WHERE id = 1;,"Error: Traceback (most recent call last):
  File "D:\python\homework\day09\db.py", line 33, in update
    cursor.execute(sql)
  File "C:\Users\yng\AppData\Local\Programs\Python\Python35\lib\site-packages\mysql\connector\cursor.py", line 515, in execute
    self._handle_result(self._connection.cmd_query(stmt))
  File "C:\Users\yng\AppData\Local\Programs\Python\Python35\lib\site-packages\mysql\connector\connection.py", line 488, in cmd_query
    result = self._handle_result(self._send_cmd(ServerCmd.QUERY, query))
  File "C:\Users\yng\AppData\Local\Programs\Python\Python35\lib\site-packages\mysql\connector\connection.py", line 395, in _handle_result
    raise errors.get_exception(packet)
mysql.connector.errors.ProgrammingError: 1054 (42S22): Unknown column 'power' in 'field list'
"
2017-09-23 07:50:03,902 db.py [line:36]-update  ERROR db "Exec: UPDATE idc SET id='1',idc_id='3',name='wwe',power='220',u_num='12' WHERE id = 1;,"Error: Traceback (most recent call last):
  File "D:\python\homework\day09\db.py", line 33, in update
    cursor.execute(sql)
  File "C:\Users\yng\AppData\Local\Programs\Python\Python35\lib\site-packages\mysql\connector\cursor.py", line 515, in execute
    self._handle_result(self._connection.cmd_query(stmt))
  File "C:\Users\yng\AppData\Local\Programs\Python\Python35\lib\site-packages\mysql\connector\connection.py", line 488, in cmd_query
    result = self._handle_result(self._send_cmd(ServerCmd.QUERY, query))
  File "C:\Users\yng\AppData\Local\Programs\Python\Python35\lib\site-packages\mysql\connector\connection.py", line 395, in _handle_result
    raise errors.get_exception(packet)
mysql.connector.errors.ProgrammingError: 1054 (42S22): Unknown column 'idc_id' in 'field list'
"
2017-09-23 07:50:41,733 db.py [line:36]-update  ERROR db "Exec: UPDATE idc SET power='220',u_num='12',name='wwe',id='1',idc_id='3' WHERE id = 1;,"Error: Traceback (most recent call last):
  File "D:\python\homework\day09\db.py", line 33, in update
    cursor.execute(sql)
  File "C:\Users\yng\AppData\Local\Programs\Python\Python35\lib\site-packages\mysql\connector\cursor.py", line 515, in execute
    self._handle_result(self._connection.cmd_query(stmt))
  File "C:\Users\yng\AppData\Local\Programs\Python\Python35\lib\site-packages\mysql\connector\connection.py", line 488, in cmd_query
    result = self._handle_result(self._send_cmd(ServerCmd.QUERY, query))
  File "C:\Users\yng\AppData\Local\Programs\Python\Python35\lib\site-packages\mysql\connector\connection.py", line 395, in _handle_result
    raise errors.get_exception(packet)
mysql.connector.errors.ProgrammingError: 1054 (42S22): Unknown column 'power' in 'field list'
"
2017-09-23 07:54:27,998 user.py [line:69]-userinfo  INFO user INFO : tailoryang is view his info 
2017-09-23 08:17:26,784 user.py [line:69]-userinfo  INFO user INFO : tailoryang is view his info 
2017-09-23 08:17:28,134 user.py [line:12]-index  INFO user "INFO: tailoryang is Is visiting"
2017-09-23 08:18:57,311 user.py [line:63]-userinfo  INFO user INFO: ['username'] is change tailoryang's info
2017-09-23 13:27:41,166 user.py [line:12]-index  INFO user "INFO: tailoryang is Is visiting"
2017-09-23 13:45:27,581 db.py [line:53]-add  ERROR db "Exec: INSERT INTO cabinet (hostname,wan_ip,lan_ip,op,cabinet_id) VALUES("W2","50.133.120.0","192.168.202.1","1","1");,"Error: Traceback (most recent call last):
  File "D:\python\homework\day09\db.py", line 50, in add
    cursor.execute(sql)
  File "C:\Users\yng\AppData\Local\Programs\Python\Python35\lib\site-packages\mysql\connector\cursor.py", line 515, in execute
    self._handle_result(self._connection.cmd_query(stmt))
  File "C:\Users\yng\AppData\Local\Programs\Python\Python35\lib\site-packages\mysql\connector\connection.py", line 488, in cmd_query
    result = self._handle_result(self._send_cmd(ServerCmd.QUERY, query))
  File "C:\Users\yng\AppData\Local\Programs\Python\Python35\lib\site-packages\mysql\connector\connection.py", line 395, in _handle_result
    raise errors.get_exception(packet)
mysql.connector.errors.ProgrammingError: 1054 (42S22): Unknown column 'hostname' in 'field list'
"
2017-09-23 13:46:10,211 db.py [line:53]-add  ERROR db "Exec: INSERT INTO cabinet (hostname,wan_ip,lan_ip,op,cabinet_id) VALUES("W2","50.133.120.0","192.168.202.1","1","1");,"Error: Traceback (most recent call last):
  File "D:\python\homework\day09\db.py", line 50, in add
    cursor.execute(sql)
  File "C:\Users\yng\AppData\Local\Programs\Python\Python35\lib\site-packages\mysql\connector\cursor.py", line 515, in execute
    self._handle_result(self._connection.cmd_query(stmt))
  File "C:\Users\yng\AppData\Local\Programs\Python\Python35\lib\site-packages\mysql\connector\connection.py", line 488, in cmd_query
    result = self._handle_result(self._send_cmd(ServerCmd.QUERY, query))
  File "C:\Users\yng\AppData\Local\Programs\Python\Python35\lib\site-packages\mysql\connector\connection.py", line 395, in _handle_result
    raise errors.get_exception(packet)
mysql.connector.errors.ProgrammingError: 1054 (42S22): Unknown column 'hostname' in 'field list'
"
2017-09-23 13:46:47,222 db.py [line:53]-add  ERROR db "Exec: INSERT INTO cabinet (hostname,wan_ip,lan_ip,op,cabinet_id) VALUES("W2","50.122.131.1","192.168.202.133","1","1");,"Error: Traceback (most recent call last):
  File "D:\python\homework\day09\db.py", line 50, in add
    cursor.execute(sql)
  File "C:\Users\yng\AppData\Local\Programs\Python\Python35\lib\site-packages\mysql\connector\cursor.py", line 515, in execute
    self._handle_result(self._connection.cmd_query(stmt))
  File "C:\Users\yng\AppData\Local\Programs\Python\Python35\lib\site-packages\mysql\connector\connection.py", line 488, in cmd_query
    result = self._handle_result(self._send_cmd(ServerCmd.QUERY, query))
  File "C:\Users\yng\AppData\Local\Programs\Python\Python35\lib\site-packages\mysql\connector\connection.py", line 395, in _handle_result
    raise errors.get_exception(packet)
mysql.connector.errors.ProgrammingError: 1054 (42S22): Unknown column 'hostname' in 'field list'
"
2017-09-23 14:43:57,976 user.py [line:69]-userinfo  INFO user INFO : tailoryang is view his info 
2017-09-23 14:44:01,536 user.py [line:63]-userinfo  INFO user INFO: ['username'] is change tailoryang's info
2017-10-14 22:17:39,769 user.py [line:28]-login  INFO user "INFO: admin is login success"
2017-10-14 22:17:41,533 user.py [line:12]-index  INFO user "INFO: admin is Is visiting"
